Workbook

Sheet Montos
A1: SUMADOR AUTOMÁTICO DE FACTURAS
A3: Factura | B3: Monto (RD$) | C3: Seleccionar (Sí/No)
A4: Fact1 | B4: 24839.64 | C4: Sí
A5: Fact2 | B5: 25310 | C5: Sí
A6: Fact3 | B6: 4710 | C6: Sí
A7: Fact4 | B7: 20228 | C7: Sí
A8: Fact5 | B8: 32439 | C8: No
A9: Fact6 | B9: 22309.54 | C9: No
A10: Fact7 | B10: 19070 | C10: No
A11: Fact8 | B11: 2754 | C11: No
A13: TOTAL DE LAS FACTURAS SELECCIONADAS: | B13: =SUMIF(C4:C11,"Sí",B4:B11) -> 75087.64
A15: INSTRUCCIONES
A16: 1. Escribe los montos de las facturas en la columna B.
A17: 2. En la columna C selecciona Sí para las facturas que se pagarán juntas.
A18: 3. El TOTAL se calcula automáticamente.
A19: 4. Puedes seleccionar de 1 a 4 facturas (o más si algún día lo necesitas).

Sheet Todas las combinaciones
A1: COMBINACIONES AUTOMÁTICAS (1 A 4 FACTURAS)
A3: Cantidad | B3: Facturas | C3: Total (RD$)
A4: 1 | B4: Fact1 | C4: =Montos!B4 -> 24839.64
A5: 1 | B5: Fact2 | C5: =Montos!B5 -> 25310
A6: 1 | B6: Fact3 | C6: =Montos!B6 -> 4710
A7: 1 | B7: Fact4 | C7: =Montos!B7 -> 20228
A8: 1 | B8: Fact5 | C8: =Montos!B8 -> 32439
A9: 1 | B9: Fact6 | C9: =Montos!B9 -> 22309.54
A10: 1 | B10: Fact7 | C10: =Montos!B10 -> 19070
A11: 1 | B11: Fact8 | C11: =Montos!B11 -> 2754
A12: 2 | B12: Fact1 + Fact2 | C12: =Montos!B4+Montos!B5 -> 50149.64
A13: 2 | B13: Fact1 + Fact3 | C13: =Montos!B4+Montos!B6 -> 29549.64
A14: 2 | B14: Fact1 + Fact4 | C14: =Montos!B4+Montos!B7 -> 45067.64
A15: 2 | B15: Fact1 + Fact5 | C15: =Montos!B4+Montos!B8 -> 57278.64
A16: 2 | B16: Fact1 + Fact6 | C16: =Montos!B4+Montos!B9 -> 47149.18
A17: 2 | B17: Fact1 + Fact7 | C17: =Montos!B4+Montos!B10 -> 43909.64
A18: 2 | B18: Fact1 + Fact8 | C18: =Montos!B4+Montos!B11 -> 27593.64
A19: 2 | B19: Fact2 + Fact3 | C19: =Montos!B5+Montos!B6 -> 30020
A20: 2 | B20: Fact2 + Fact4 | C20: =Montos!B5+Montos!B7 -> 45538
A21: 2 | B21: Fact2 + Fact5 | C21: =Montos!B5+Montos!B8 -> 57749
A22: 2 | B22: Fact2 + Fact6 | C22: =Montos!B5+Montos!B9 -> 47619.54
A23: 2 | B23: Fact2 + Fact7 | C23: =Montos!B5+Montos!B10 -> 44380
A24: 2 | B24: Fact2 + Fact8 | C24: =Montos!B5+Montos!B11 -> 28064
A25: 2 | B25: Fact3 + Fact4 | C25: =Montos!B6+Montos!B7 -> 24938
A26: 2 | B26: Fact3 + Fact5 | C26: =Montos!B6+Montos!B8 -> 37149
A27: 2 | B27: Fact3 + Fact6 | C27: =Montos!B6+Montos!B9 -> 27019.54
A28: 2 | B28: Fact3 + Fact7 | C28: =Montos!B6+Montos!B10 -> 23780
A29: 2 | B29: Fact3 + Fact8 | C29: =Montos!B6+Montos!B11 -> 7464
A30: 2 | B30: Fact4 + Fact5 | C30: =Montos!B7+Montos!B8 -> 52667
A31: 2 | B31: Fact4 + Fact6 | C31: =Montos!B7+Montos!B9 -> 42537.54
A32: 2 | B32: Fact4 + Fact7 | C32: =Montos!B7+Montos!B10 -> 39298
A33: 2 | B33: Fact4 + Fact8 | C33: =Montos!B7+Montos!B11 -> 22982
A34: 2 | B34: Fact5 + Fact6 | C34: =Montos!B8+Montos!B9 -> 54748.54
A35: 2 | B35: Fact5 + Fact7 | C35: =Montos!B8+Montos!B10 -> 51509
A36: 2 | B36: Fact5 + Fact8 | C36: =Montos!B8+Montos!B11 -> 35193
A37: 2 | B37: Fact6 + Fact7 | C37: =Montos!B9+Montos!B10 -> 41379.54
A38: 2 | B38: Fact6 + Fact8 | C38: =Montos!B9+Montos!B11 -> 25063.54
A39: 2 | B39: Fact7 + Fact8 | C39: =Montos!B10+Montos!B11 -> 21824
A40: 3 | B40: Fact1 + Fact2 + Fact3 | C40: =Montos!B4+Montos!B5+Montos!B6 -> 54859.64
A41: 3 | B41: Fact1 + Fact2 + Fact4 | C41: =Montos!B4+Montos!B5+Montos!B7 -> 70377.64
...

Sheet Ejemplo
A1: EJEMPLO CON TUS MONTOS
A3: Factura | B3: Monto (RD$)
A4: Fact1 | B4: 24839.64
A5: Fact2 | B5: 25310
A6: Fact3 | B6: 4710
A7: Fact4 | B7: 20228.2
A8: Fact5 | B8: 32439
A9: Fact6 | B9: 22309.54
A10: Fact7 | B10: 19070
A11: Fact8 | B11: 2754
A14: Puedes copiar estos montos a la hoja 'Montos' o reemplazarlos.
